[2023-09-12 04:51:49,332] {taskinstance.py:1179} INFO - Dependencies all met for <TaskInstance: CallPostgreOperator.get_data manual__2023-09-12T04:39:59.483029+00:00 [queued]>
[2023-09-12 04:51:49,341] {taskinstance.py:1179} INFO - Dependencies all met for <TaskInstance: CallPostgreOperator.get_data manual__2023-09-12T04:39:59.483029+00:00 [queued]>
[2023-09-12 04:51:49,341] {taskinstance.py:1376} INFO - 
--------------------------------------------------------------------------------
[2023-09-12 04:51:49,341] {taskinstance.py:1377} INFO - Starting attempt 2 of 2
[2023-09-12 04:51:49,341] {taskinstance.py:1378} INFO - 
--------------------------------------------------------------------------------
[2023-09-12 04:51:49,355] {taskinstance.py:1397} INFO - Executing <Task(PythonOperator): get_data> on 2023-09-12 04:39:59.483029+00:00
[2023-09-12 04:51:49,389] {standard_task_runner.py:52} INFO - Started process 1007 to run task
[2023-09-12 04:51:49,392] {standard_task_runner.py:79} INFO - Running: ['***', 'tasks', 'run', 'CallPostgreOperator', 'get_data', 'manual__2023-09-12T04:39:59.483029+00:00', '--job-id', '956', '--raw', '--subdir', 'DAGS_FOLDER/CallPostgreOperator.py', '--cfg-path', '/tmp/tmp1w9_zikz', '--error-file', '/tmp/tmpc54bygz0']
[2023-09-12 04:51:49,393] {standard_task_runner.py:80} INFO - Job 956: Subtask get_data
[2023-09-12 04:51:49,459] {task_command.py:371} INFO - Running <TaskInstance: CallPostgreOperator.get_data manual__2023-09-12T04:39:59.483029+00:00 [running]> on host b18943745c0d
[2023-09-12 04:51:49,490] {warnings.py:110} WARNING - /home/***/.local/lib/python3.7/site-packages/***/utils/context.py:202: AirflowContextDeprecationWarning: Accessing 'execution_date' from the template is deprecated and will be removed in a future version. Please use 'data_interval_start' or 'logical_date' instead.
  warnings.warn(_create_deprecation_warning(key, self._deprecation_replacements[key]))

[2023-09-12 04:51:49,526] {taskinstance.py:1591} INFO - Exporting the following env vars:
AIRFLOW_CTX_DAG_OWNER=***
AIRFLOW_CTX_DAG_ID=CallPostgreOperator
AIRFLOW_CTX_TASK_ID=get_data
AIRFLOW_CTX_EXECUTION_DATE=2023-09-12T04:39:59.483029+00:00
AIRFLOW_CTX_TRY_NUMBER=2
AIRFLOW_CTX_DAG_RUN_ID=manual__2023-09-12T04:39:59.483029+00:00
[2023-09-12 04:53:11,494] {taskinstance.py:1909} ERROR - Task failed with exception
Traceback (most recent call last):
  File "/home/airflow/.local/lib/python3.7/site-packages/airflow/operators/python.py", line 171, in execute
    return_value = self.execute_callable()
  File "/home/airflow/.local/lib/python3.7/site-packages/airflow/operators/python.py", line 189, in execute_callable
    return self.python_callable(*self.op_args, **self.op_kwargs)
  File "/opt/airflow/dags/CallPostgreOperator.py", line 27, in _get_data
    request.urlretrieve(url, output_path)
  File "/usr/local/lib/python3.7/urllib/request.py", line 247, in urlretrieve
    with contextlib.closing(urlopen(url, data)) as fp:
  File "/usr/local/lib/python3.7/urllib/request.py", line 222, in urlopen
    return opener.open(url, data, timeout)
  File "/usr/local/lib/python3.7/urllib/request.py", line 525, in open
    response = self._open(req, data)
  File "/usr/local/lib/python3.7/urllib/request.py", line 543, in _open
    '_open', req)
  File "/usr/local/lib/python3.7/urllib/request.py", line 503, in _call_chain
    result = func(*args)
  File "/usr/local/lib/python3.7/urllib/request.py", line 1393, in https_open
    context=self._context, check_hostname=self._check_hostname)
  File "/usr/local/lib/python3.7/urllib/request.py", line 1353, in do_open
    r = h.getresponse()
  File "/usr/local/lib/python3.7/http/client.py", line 1373, in getresponse
    response.begin()
  File "/usr/local/lib/python3.7/http/client.py", line 319, in begin
    version, status, reason = self._read_status()
  File "/usr/local/lib/python3.7/http/client.py", line 288, in _read_status
    raise RemoteDisconnected("Remote end closed connection without"
http.client.RemoteDisconnected: Remote end closed connection without response
[2023-09-12 04:53:11,502] {taskinstance.py:1420} INFO - Marking task as FAILED. dag_id=CallPostgreOperator, task_id=get_data, execution_date=20230912T043959, start_date=20230912T045149, end_date=20230912T045311
[2023-09-12 04:53:11,516] {standard_task_runner.py:97} ERROR - Failed to execute job 956 for task get_data (Remote end closed connection without response; 1007)
[2023-09-12 04:53:11,535] {local_task_job.py:156} INFO - Task exited with return code 1
[2023-09-12 04:53:11,573] {local_task_job.py:273} INFO - 0 downstream tasks scheduled from follow-on schedule check
