[2023-09-12 00:19:55,695] {taskinstance.py:1179} INFO - Dependencies all met for <TaskInstance: CallPostgreOperator.write_to_postgres scheduled__2023-09-11T00:00:00+00:00 [queued]>
[2023-09-12 00:19:55,713] {taskinstance.py:1179} INFO - Dependencies all met for <TaskInstance: CallPostgreOperator.write_to_postgres scheduled__2023-09-11T00:00:00+00:00 [queued]>
[2023-09-12 00:19:55,713] {taskinstance.py:1376} INFO - 
--------------------------------------------------------------------------------
[2023-09-12 00:19:55,713] {taskinstance.py:1377} INFO - Starting attempt 1 of 1
[2023-09-12 00:19:55,713] {taskinstance.py:1378} INFO - 
--------------------------------------------------------------------------------
[2023-09-12 00:19:55,739] {taskinstance.py:1397} INFO - Executing <Task(PostgresOperator): write_to_postgres> on 2023-09-11 00:00:00+00:00
[2023-09-12 00:19:55,746] {standard_task_runner.py:52} INFO - Started process 22299 to run task
[2023-09-12 00:19:55,751] {standard_task_runner.py:79} INFO - Running: ['***', 'tasks', 'run', 'CallPostgreOperator', 'write_to_postgres', 'scheduled__2023-09-11T00:00:00+00:00', '--job-id', '916', '--raw', '--subdir', 'DAGS_FOLDER/CallPostgreOperator.py', '--cfg-path', '/tmp/tmpjrr9awa4', '--error-file', '/tmp/tmpqnf033h5']
[2023-09-12 00:19:55,752] {standard_task_runner.py:80} INFO - Job 916: Subtask write_to_postgres
[2023-09-12 00:19:55,856] {task_command.py:371} INFO - Running <TaskInstance: CallPostgreOperator.write_to_postgres scheduled__2023-09-11T00:00:00+00:00 [running]> on host b18943745c0d
[2023-09-12 00:19:55,970] {taskinstance.py:1591} INFO - Exporting the following env vars:
AIRFLOW_CTX_DAG_OWNER=***
AIRFLOW_CTX_DAG_ID=CallPostgreOperator
AIRFLOW_CTX_TASK_ID=write_to_postgres
AIRFLOW_CTX_EXECUTION_DATE=2023-09-11T00:00:00+00:00
AIRFLOW_CTX_TRY_NUMBER=1
AIRFLOW_CTX_DAG_RUN_ID=scheduled__2023-09-11T00:00:00+00:00
[2023-09-12 00:19:56,002] {taskinstance.py:1909} ERROR - Task failed with exception
Traceback (most recent call last):
  File "/home/airflow/.local/lib/python3.7/site-packages/airflow/providers/postgres/operators/postgres.py", line 92, in execute
    self.hook.run(self.sql, self.autocommit, parameters=self.parameters)
  File "/home/airflow/.local/lib/python3.7/site-packages/airflow/hooks/dbapi.py", line 204, in run
    with closing(self.get_conn()) as conn:
  File "/home/airflow/.local/lib/python3.7/site-packages/airflow/providers/postgres/hooks/postgres.py", line 86, in get_conn
    conn = deepcopy(self.connection or self.get_connection(conn_id))
  File "/home/airflow/.local/lib/python3.7/site-packages/airflow/hooks/base.py", line 67, in get_connection
    conn = Connection.get_connection_from_secrets(conn_id)
  File "/home/airflow/.local/lib/python3.7/site-packages/airflow/models/connection.py", line 430, in get_connection_from_secrets
    raise AirflowNotFoundException(f"The conn_id `{conn_id}` isn't defined")
airflow.exceptions.AirflowNotFoundException: The conn_id `postgres` isn't defined
[2023-09-12 00:19:56,009] {taskinstance.py:1420} INFO - Marking task as FAILED. dag_id=CallPostgreOperator, task_id=write_to_postgres, execution_date=20230911T000000, start_date=20230912T001955, end_date=20230912T001956
[2023-09-12 00:19:56,026] {standard_task_runner.py:97} ERROR - Failed to execute job 916 for task write_to_postgres (The conn_id `postgres` isn't defined; 22299)
[2023-09-12 00:19:56,043] {local_task_job.py:156} INFO - Task exited with return code 1
[2023-09-12 00:19:56,092] {local_task_job.py:273} INFO - 0 downstream tasks scheduled from follow-on schedule check
[2023-09-12 04:42:59,498] {taskinstance.py:1179} INFO - Dependencies all met for <TaskInstance: CallPostgreOperator.write_to_postgres scheduled__2023-09-11T00:00:00+00:00 [queued]>
[2023-09-12 04:42:59,508] {taskinstance.py:1179} INFO - Dependencies all met for <TaskInstance: CallPostgreOperator.write_to_postgres scheduled__2023-09-11T00:00:00+00:00 [queued]>
[2023-09-12 04:42:59,509] {taskinstance.py:1376} INFO - 
--------------------------------------------------------------------------------
[2023-09-12 04:42:59,509] {taskinstance.py:1377} INFO - Starting attempt 1 of 1
[2023-09-12 04:42:59,509] {taskinstance.py:1378} INFO - 
--------------------------------------------------------------------------------
[2023-09-12 04:42:59,524] {taskinstance.py:1397} INFO - Executing <Task(PostgresOperator): write_to_postgres> on 2023-09-11 00:00:00+00:00
[2023-09-12 04:42:59,528] {standard_task_runner.py:52} INFO - Started process 581 to run task
[2023-09-12 04:42:59,531] {standard_task_runner.py:79} INFO - Running: ['***', 'tasks', 'run', 'CallPostgreOperator', 'write_to_postgres', 'scheduled__2023-09-11T00:00:00+00:00', '--job-id', '951', '--raw', '--subdir', 'DAGS_FOLDER/CallPostgreOperator.py', '--cfg-path', '/tmp/tmp3b381obn', '--error-file', '/tmp/tmpne78h_rm']
[2023-09-12 04:42:59,531] {standard_task_runner.py:80} INFO - Job 951: Subtask write_to_postgres
[2023-09-12 04:42:59,610] {task_command.py:371} INFO - Running <TaskInstance: CallPostgreOperator.write_to_postgres scheduled__2023-09-11T00:00:00+00:00 [running]> on host b18943745c0d
[2023-09-12 04:42:59,721] {taskinstance.py:1591} INFO - Exporting the following env vars:
AIRFLOW_CTX_DAG_OWNER=***
AIRFLOW_CTX_DAG_ID=CallPostgreOperator
AIRFLOW_CTX_TASK_ID=write_to_postgres
AIRFLOW_CTX_EXECUTION_DATE=2023-09-11T00:00:00+00:00
AIRFLOW_CTX_TRY_NUMBER=1
AIRFLOW_CTX_DAG_RUN_ID=scheduled__2023-09-11T00:00:00+00:00
[2023-09-12 04:42:59,738] {base.py:68} INFO - Using connection ID 'my_postgres' for task execution.
[2023-09-12 04:42:59,742] {taskinstance.py:1909} ERROR - Task failed with exception
Traceback (most recent call last):
  File "/home/airflow/.local/lib/python3.7/site-packages/airflow/providers/postgres/operators/postgres.py", line 92, in execute
    self.hook.run(self.sql, self.autocommit, parameters=self.parameters)
  File "/home/airflow/.local/lib/python3.7/site-packages/airflow/hooks/dbapi.py", line 204, in run
    with closing(self.get_conn()) as conn:
  File "/home/airflow/.local/lib/python3.7/site-packages/airflow/providers/postgres/hooks/postgres.py", line 113, in get_conn
    self.conn = psycopg2.connect(**conn_args)
  File "/home/airflow/.local/lib/python3.7/site-packages/psycopg2/__init__.py", line 122, in connect
    conn = _connect(dsn, connection_factory=connection_factory, **kwasync)
psycopg2.OperationalError: connection to server at "localhost" (127.0.0.1), port 5432 failed: Connection refused
	Is the server running on that host and accepting TCP/IP connections?
connection to server at "localhost" (::1), port 5432 failed: Cannot assign requested address
	Is the server running on that host and accepting TCP/IP connections?

[2023-09-12 04:42:59,783] {taskinstance.py:1420} INFO - Marking task as FAILED. dag_id=CallPostgreOperator, task_id=write_to_postgres, execution_date=20230911T000000, start_date=20230912T044259, end_date=20230912T044259
[2023-09-12 04:42:59,796] {standard_task_runner.py:97} ERROR - Failed to execute job 951 for task write_to_postgres (connection to server at "localhost" (127.0.0.1), port 5432 failed: Connection refused
	Is the server running on that host and accepting TCP/IP connections?
connection to server at "localhost" (::1), port 5432 failed: Cannot assign requested address
	Is the server running on that host and accepting TCP/IP connections?
; 581)
[2023-09-12 04:42:59,824] {local_task_job.py:156} INFO - Task exited with return code 1
[2023-09-12 04:42:59,895] {local_task_job.py:273} INFO - 0 downstream tasks scheduled from follow-on schedule check
