[2023-09-09 15:39:34,946] {taskinstance.py:1179} INFO - Dependencies all met for <TaskInstance: download_rocket_launches.get_pictures manual__2023-09-09T15:39:31.372534+00:00 [queued]>
[2023-09-09 15:39:34,957] {taskinstance.py:1179} INFO - Dependencies all met for <TaskInstance: download_rocket_launches.get_pictures manual__2023-09-09T15:39:31.372534+00:00 [queued]>
[2023-09-09 15:39:34,958] {taskinstance.py:1376} INFO - 
--------------------------------------------------------------------------------
[2023-09-09 15:39:34,958] {taskinstance.py:1377} INFO - Starting attempt 1 of 1
[2023-09-09 15:39:34,958] {taskinstance.py:1378} INFO - 
--------------------------------------------------------------------------------
[2023-09-09 15:39:34,973] {taskinstance.py:1397} INFO - Executing <Task(PythonOperator): get_pictures> on 2023-09-09 15:39:31.372534+00:00
[2023-09-09 15:39:34,976] {standard_task_runner.py:52} INFO - Started process 19786 to run task
[2023-09-09 15:39:34,979] {standard_task_runner.py:79} INFO - Running: ['***', 'tasks', 'run', 'download_rocket_launches', 'get_pictures', 'manual__2023-09-09T15:39:31.372534+00:00', '--job-id', '112', '--raw', '--subdir', 'DAGS_FOLDER/download_rocket_launches.py', '--cfg-path', '/tmp/tmp2mhtjy91', '--error-file', '/tmp/tmpn26h2hge']
[2023-09-09 15:39:34,979] {standard_task_runner.py:80} INFO - Job 112: Subtask get_pictures
[2023-09-09 15:39:35,045] {task_command.py:371} INFO - Running <TaskInstance: download_rocket_launches.get_pictures manual__2023-09-09T15:39:31.372534+00:00 [running]> on host b18943745c0d
[2023-09-09 15:39:35,125] {taskinstance.py:1591} INFO - Exporting the following env vars:
AIRFLOW_CTX_DAG_OWNER=***
AIRFLOW_CTX_DAG_ID=download_rocket_launches
AIRFLOW_CTX_TASK_ID=get_pictures
AIRFLOW_CTX_EXECUTION_DATE=2023-09-09T15:39:31.372534+00:00
AIRFLOW_CTX_TRY_NUMBER=1
AIRFLOW_CTX_DAG_RUN_ID=manual__2023-09-09T15:39:31.372534+00:00
[2023-09-09 15:39:35,126] {taskinstance.py:1909} ERROR - Task failed with exception
Traceback (most recent call last):
  File "/usr/local/lib/python3.7/pathlib.py", line 1273, in mkdir
    self._accessor.mkdir(self, mode)
FileNotFoundError: [Errno 2] No such file or directory: '/home/gloryword/airflow/tmp/images'

During handling of the above exception, another exception occurred:

Traceback (most recent call last):
  File "/usr/local/lib/python3.7/pathlib.py", line 1273, in mkdir
    self._accessor.mkdir(self, mode)
FileNotFoundError: [Errno 2] No such file or directory: '/home/gloryword/airflow/tmp'

During handling of the above exception, another exception occurred:

Traceback (most recent call last):
  File "/usr/local/lib/python3.7/pathlib.py", line 1273, in mkdir
    self._accessor.mkdir(self, mode)
FileNotFoundError: [Errno 2] No such file or directory: '/home/gloryword/airflow'

During handling of the above exception, another exception occurred:

Traceback (most recent call last):
  File "/home/airflow/.local/lib/python3.7/site-packages/airflow/operators/python.py", line 171, in execute
    return_value = self.execute_callable()
  File "/home/airflow/.local/lib/python3.7/site-packages/airflow/operators/python.py", line 189, in execute_callable
    return self.python_callable(*self.op_args, **self.op_kwargs)
  File "/opt/airflow/dags/download_rocket_launches.py", line 28, in _get_pictures
    pathlib.Path("/home/gloryword/airflow/tmp/images").mkdir(parents=True, exist_ok=True) # parents=True : 중간 경로들 없으면 알아서 생성, exist_ok=True : 이미 존재해도 에러발생 X
  File "/usr/local/lib/python3.7/pathlib.py", line 1277, in mkdir
    self.parent.mkdir(parents=True, exist_ok=True)
  File "/usr/local/lib/python3.7/pathlib.py", line 1277, in mkdir
    self.parent.mkdir(parents=True, exist_ok=True)
  File "/usr/local/lib/python3.7/pathlib.py", line 1277, in mkdir
    self.parent.mkdir(parents=True, exist_ok=True)
  File "/usr/local/lib/python3.7/pathlib.py", line 1273, in mkdir
    self._accessor.mkdir(self, mode)
PermissionError: [Errno 13] Permission denied: '/home/gloryword'
[2023-09-09 15:39:35,137] {taskinstance.py:1420} INFO - Marking task as FAILED. dag_id=download_rocket_launches, task_id=get_pictures, execution_date=20230909T153931, start_date=20230909T153934, end_date=20230909T153935
[2023-09-09 15:39:35,152] {standard_task_runner.py:97} ERROR - Failed to execute job 112 for task get_pictures ([Errno 13] Permission denied: '/home/gloryword'; 19786)
[2023-09-09 15:39:35,191] {local_task_job.py:156} INFO - Task exited with return code 1
[2023-09-09 15:39:35,229] {local_task_job.py:273} INFO - 0 downstream tasks scheduled from follow-on schedule check
