[2023-09-12 04:48:43,467] {taskinstance.py:1179} INFO - Dependencies all met for <TaskInstance: CallPostgreOperator.get_data scheduled__2023-09-11T01:00:00+00:00 [queued]>
[2023-09-12 04:48:43,476] {taskinstance.py:1179} INFO - Dependencies all met for <TaskInstance: CallPostgreOperator.get_data scheduled__2023-09-11T01:00:00+00:00 [queued]>
[2023-09-12 04:48:43,477] {taskinstance.py:1376} INFO - 
--------------------------------------------------------------------------------
[2023-09-12 04:48:43,477] {taskinstance.py:1377} INFO - Starting attempt 2 of 2
[2023-09-12 04:48:43,477] {taskinstance.py:1378} INFO - 
--------------------------------------------------------------------------------
[2023-09-12 04:48:43,491] {taskinstance.py:1397} INFO - Executing <Task(PythonOperator): get_data> on 2023-09-11 01:00:00+00:00
[2023-09-12 04:48:43,495] {standard_task_runner.py:52} INFO - Started process 861 to run task
[2023-09-12 04:48:43,498] {standard_task_runner.py:79} INFO - Running: ['***', 'tasks', 'run', 'CallPostgreOperator', 'get_data', 'scheduled__2023-09-11T01:00:00+00:00', '--job-id', '955', '--raw', '--subdir', 'DAGS_FOLDER/CallPostgreOperator.py', '--cfg-path', '/tmp/tmps6td3hrr', '--error-file', '/tmp/tmp4mgh0bcz']
[2023-09-12 04:48:43,498] {standard_task_runner.py:80} INFO - Job 955: Subtask get_data
[2023-09-12 04:48:43,557] {task_command.py:371} INFO - Running <TaskInstance: CallPostgreOperator.get_data scheduled__2023-09-11T01:00:00+00:00 [running]> on host b18943745c0d
[2023-09-12 04:48:43,587] {warnings.py:110} WARNING - /home/***/.local/lib/python3.7/site-packages/***/utils/context.py:202: AirflowContextDeprecationWarning: Accessing 'execution_date' from the template is deprecated and will be removed in a future version. Please use 'data_interval_start' or 'logical_date' instead.
  warnings.warn(_create_deprecation_warning(key, self._deprecation_replacements[key]))

[2023-09-12 04:48:43,624] {taskinstance.py:1591} INFO - Exporting the following env vars:
AIRFLOW_CTX_DAG_OWNER=***
AIRFLOW_CTX_DAG_ID=CallPostgreOperator
AIRFLOW_CTX_TASK_ID=get_data
AIRFLOW_CTX_EXECUTION_DATE=2023-09-11T01:00:00+00:00
AIRFLOW_CTX_TRY_NUMBER=2
AIRFLOW_CTX_DAG_RUN_ID=scheduled__2023-09-11T01:00:00+00:00
[2023-09-12 04:51:45,927] {taskinstance.py:1909} ERROR - Task failed with exception
Traceback (most recent call last):
  File "/usr/local/lib/python3.7/urllib/request.py", line 1350, in do_open
    encode_chunked=req.has_header('Transfer-encoding'))
  File "/usr/local/lib/python3.7/http/client.py", line 1281, in request
    self._send_request(method, url, body, headers, encode_chunked)
  File "/usr/local/lib/python3.7/http/client.py", line 1327, in _send_request
    self.endheaders(body, encode_chunked=encode_chunked)
  File "/usr/local/lib/python3.7/http/client.py", line 1276, in endheaders
    self._send_output(message_body, encode_chunked=encode_chunked)
  File "/usr/local/lib/python3.7/http/client.py", line 1036, in _send_output
    self.send(msg)
  File "/usr/local/lib/python3.7/http/client.py", line 976, in send
    self.connect()
  File "/usr/local/lib/python3.7/http/client.py", line 1451, in connect
    server_hostname=server_hostname)
  File "/usr/local/lib/python3.7/ssl.py", line 423, in wrap_socket
    session=session
  File "/usr/local/lib/python3.7/ssl.py", line 870, in _create
    self.do_handshake()
  File "/usr/local/lib/python3.7/ssl.py", line 1139, in do_handshake
    self._sslobj.do_handshake()
OSError: [Errno 0] Error

During handling of the above exception, another exception occurred:

Traceback (most recent call last):
  File "/home/airflow/.local/lib/python3.7/site-packages/airflow/operators/python.py", line 171, in execute
    return_value = self.execute_callable()
  File "/home/airflow/.local/lib/python3.7/site-packages/airflow/operators/python.py", line 189, in execute_callable
    return self.python_callable(*self.op_args, **self.op_kwargs)
  File "/opt/airflow/dags/CallPostgreOperator.py", line 27, in _get_data
    request.urlretrieve(url, output_path)
  File "/usr/local/lib/python3.7/urllib/request.py", line 247, in urlretrieve
    with contextlib.closing(urlopen(url, data)) as fp:
  File "/usr/local/lib/python3.7/urllib/request.py", line 222, in urlopen
    return opener.open(url, data, timeout)
  File "/usr/local/lib/python3.7/urllib/request.py", line 525, in open
    response = self._open(req, data)
  File "/usr/local/lib/python3.7/urllib/request.py", line 543, in _open
    '_open', req)
  File "/usr/local/lib/python3.7/urllib/request.py", line 503, in _call_chain
    result = func(*args)
  File "/usr/local/lib/python3.7/urllib/request.py", line 1393, in https_open
    context=self._context, check_hostname=self._check_hostname)
  File "/usr/local/lib/python3.7/urllib/request.py", line 1352, in do_open
    raise URLError(err)
urllib.error.URLError: <urlopen error [Errno 0] Error>
[2023-09-12 04:51:45,946] {taskinstance.py:1420} INFO - Marking task as FAILED. dag_id=CallPostgreOperator, task_id=get_data, execution_date=20230911T010000, start_date=20230912T044843, end_date=20230912T045145
[2023-09-12 04:51:45,958] {standard_task_runner.py:97} ERROR - Failed to execute job 955 for task get_data (<urlopen error [Errno 0] Error>; 861)
[2023-09-12 04:51:45,982] {local_task_job.py:156} INFO - Task exited with return code 1
[2023-09-12 04:51:46,016] {local_task_job.py:273} INFO - 0 downstream tasks scheduled from follow-on schedule check
